Workbook

Sheet 61111-0002
A1: Consumer price index: Germany, months
A2: Consumer price index for Germany
A3: Germany
A4: Year Months | C4: Consumer price index | E4: Change on previous year's month | G4: Change on previous month
C5: 2020=100 | E5: in (%) | G5: in (%)
A6: 2000 | B6: January | C6: 75.1 | D6: e | E6: 1.6 | F6: e | G6: 0.3 | H6: e
B7: February | C7: 75.1 | D7: e | E7: 1.5 | F7: e | G7: -
B8: March | C8: 75.1 | D8: e | E8: 1.5 | F8: e | G8: -
B9: April | C9: 75.1 | D9: e | E9: 0.9 | F9: e | G9: -
B10: May | C10: 75.1 | D10: e | E10: 0.9 | F10: e | G10: -
B11: June | C11: 75.4 | D11: e | E11: 1.2 | F11: e | G11: 0.4 | H11: e
B12: July | C12: 75.8 | D12: e | E12: 1.3 | F12: e | G12: 0.5 | H12: e
B13: August | C13: 75.6 | D13: e | E13: 1.1 | F13: e | G13: -0.3 | H13: e
B14: September | C14: 75.8 | D14: e | E14: 1.6 | F14: e | G14: 0.3 | H14: e
B15: October | C15: 75.7 | D15: e | E15: 1.6 | F15: e | G15: -0.1 | H15: e
B16: November | C16: 75.8 | D16: e | E16: 1.5 | F16: e | G16: 0.1 | H16: e
B17: December | C17: 76.4 | D17: e | E17: 2 | F17: e | G17: 0.8 | H17: e
A18: 2001 | B18: January | C18: 76.2 | D18: e | E18: 1.5 | F18: e | G18: -0.3 | H18: e
B19: February | C19: 76.6 | D19: e | E19: 2 | F19: e | G19: 0.5 | H19: e
B20: March | C20: 76.6 | D20: e | E20: 2 | F20: e | G20: -
B21: April | C21: 76.9 | D21: e | E21: 2.4 | F21: e | G21: 0.4 | H21: e
B22: May | C22: 77.2 | D22: e | E22: 2.8 | F22: e | G22: 0.4 | H22: e
B23: June | C23: 77.3 | D23: e | E23: 2.5 | F23: e | G23: 0.1 | H23: e
B24: July | C24: 77.4 | D24: e | E24: 2.1 | F24: e | G24: 0.1 | H24: e
B25: August | C25: 77.2 | D25: e | E25: 2.1 | F25: e | G25: -0.3 | H25: e
B26: September | C26: 77.2 | D26: e | E26: 1.8 | F26: e | G26: -
B27: October | C27: 77.1 | D27: e | E27: 1.8 | F27: e | G27: -0.1 | H27: e
B28: November | C28: 76.9 | D28: e | E28: 1.5 | F28: e | G28: -0.3 | H28: e
B29: December | C29: 77.7 | D29: e | E29: 1.7 | F29: e | G29: 1 | H29: e
A30: 2002 | B30: January | C30: 77.7 | D30: e | E30: 2 | F30: e | G30: -
B31: February | C31: 78 | D31: e | E31: 1.8 | F31: e | G31: 0.4 | H31: e
B32: March | C32: 78.2 | D32: e | E32: 2.1 | F32: e | G32: 0.3 | H32: e
B33: April | C33: 78.1 | D33: e | E33: 1.6 | F33: e | G33: -0.1 | H33: e
B34: May | C34: 78.2 | D34: e | E34: 1.3 | F34: e | G34: 0.1 | H34: e
B35: June | C35: 78.2 | D35: e | E35: 1.2 | F35: e | G35: -
B36: July | C36: 78.3 | D36: e | E36: 1.2 | F36: e | G36: 0.1 | H36: e
B37: August | C37: 78.2 | D37: e | E37: 1.3 | F37: e | G37: -0.1 | H37: e
B38: September | C38: 78.2 | D38: e | E38: 1.3 | F38: e | G38: -
B39: October | C39: 78.1 | D39: e | E39: 1.3 | F39: e | G39: -0.1 | H39: e
B40: November | C40: 77.8 | D40: e | E40: 1.2 | F40: e | G40: -0.4 | H40: e
...

Sheet Daten
A1: Jahr | B1: Monat | C1: Inflation
A2: 2000 | B2: 1 | C2: ='61111-0002'!E6 -> 1.6
A3: 2000 | B3: 2 | C3: ='61111-0002'!E7 -> 1.5
A4: 2000 | B4: 3 | C4: ='61111-0002'!E8 -> 1.5
A5: 2000 | B5: 4 | C5: ='61111-0002'!E9 -> 0.9
A6: 2000 | B6: 5 | C6: ='61111-0002'!E10 -> 0.9
A7: 2000 | B7: 6 | C7: ='61111-0002'!E11 -> 1.2
A8: 2000 | B8: 7 | C8: ='61111-0002'!E12 -> 1.3
A9: 2000 | B9: 8 | C9: ='61111-0002'!E13 -> 1.1
A10: 2000 | B10: 9 | C10: ='61111-0002'!E14 -> 1.6
A11: 2000 | B11: 10 | C11: ='61111-0002'!E15 -> 1.6
A12: 2000 | B12: 11 | C12: ='61111-0002'!E16 -> 1.5
A13: 2000 | B13: 12 | C13: ='61111-0002'!E17 -> 2
... A312: 2025 | B312: 11 | C312: ='61111-0002'!E316 -> 2.3
